[2024-05-01T16:17:05.971+0000] {taskinstance.py:1125} INFO - Dependencies all met for dep_context=non-requeueable deps ti=<TaskInstance: diabetes_prediction.preprocess_data manual__2024-05-01T16:16:52.900377+00:00 [queued]>
[2024-05-01T16:17:06.005+0000] {taskinstance.py:1125} INFO - Dependencies all met for dep_context=requeueable deps ti=<TaskInstance: diabetes_prediction.preprocess_data manual__2024-05-01T16:16:52.900377+00:00 [queued]>
[2024-05-01T16:17:06.005+0000] {taskinstance.py:1331} INFO - Starting attempt 1 of 2
[2024-05-01T16:17:06.058+0000] {taskinstance.py:1350} INFO - Executing <Task(PythonOperator): preprocess_data> on 2024-05-01 16:16:52.900377+00:00
[2024-05-01T16:17:06.075+0000] {standard_task_runner.py:57} INFO - Started process 788 to run task
[2024-05-01T16:17:06.083+0000] {standard_task_runner.py:84} INFO - Running: ['***', 'tasks', 'run', 'diabetes_prediction', 'preprocess_data', 'manual__2024-05-01T16:16:52.900377+00:00', '--job-id', '36', '--raw', '--subdir', 'DAGS_FOLDER/dag1.py', '--cfg-path', '/tmp/tmp8wnizym1']
[2024-05-01T16:17:06.089+0000] {standard_task_runner.py:85} INFO - Job 36: Subtask preprocess_data
[2024-05-01T16:17:06.257+0000] {task_command.py:410} INFO - Running <TaskInstance: diabetes_prediction.preprocess_data manual__2024-05-01T16:16:52.900377+00:00 [running]> on host c90068845469
[2024-05-01T16:17:06.539+0000] {taskinstance.py:1570} INFO - Exporting env vars: AIRFLOW_CTX_DAG_OWNER='***' AIRFLOW_CTX_DAG_ID='diabetes_prediction' AIRFLOW_CTX_TASK_ID='preprocess_data' AIRFLOW_CTX_EXECUTION_DATE='2024-05-01T16:16:52.900377+00:00' AIRFLOW_CTX_TRY_NUMBER='1' AIRFLOW_CTX_DAG_RUN_ID='manual__2024-05-01T16:16:52.900377+00:00'
[2024-05-01T16:17:06.570+0000] {logging_mixin.py:149} INFO - 1
[2024-05-01T16:17:06.571+0000] {logging_mixin.py:149} INFO - <class 'NoneType'>
[2024-05-01T16:17:06.571+0000] {taskinstance.py:1847} ERROR - Task failed with exception
Traceback (most recent call last):
  File "/home/airflow/.local/lib/python3.7/site-packages/airflow/operators/python.py", line 181, in execute
    return_value = self.execute_callable()
  File "/home/airflow/.local/lib/python3.7/site-packages/airflow/operators/python.py", line 198, in execute_callable
    return self.python_callable(*self.op_args, **self.op_kwargs)
  File "/opt/airflow/dags/dag1.py", line 32, in preprocess_data
    X = dataset.loc[:, dataset.columns!='readmitted']
AttributeError: 'NoneType' object has no attribute 'loc'
[2024-05-01T16:17:06.599+0000] {taskinstance.py:1373} INFO - Marking task as UP_FOR_RETRY. dag_id=diabetes_prediction, task_id=preprocess_data, execution_date=20240501T161652, start_date=20240501T161705, end_date=20240501T161706
[2024-05-01T16:17:06.632+0000] {standard_task_runner.py:109} ERROR - Failed to execute job 36 for task preprocess_data ('NoneType' object has no attribute 'loc'; 788)
[2024-05-01T16:17:06.653+0000] {local_task_job_runner.py:232} INFO - Task exited with return code 1
[2024-05-01T16:17:06.728+0000] {taskinstance.py:2674} INFO - 0 downstream tasks scheduled from follow-on schedule check
