[2024-05-01T16:38:29.631+0000] {taskinstance.py:1125} INFO - Dependencies all met for dep_context=non-requeueable deps ti=<TaskInstance: diabetes_prediction.train_model manual__2024-05-01T16:27:46.554638+00:00 [queued]>
[2024-05-01T16:38:29.659+0000] {taskinstance.py:1125} INFO - Dependencies all met for dep_context=requeueable deps ti=<TaskInstance: diabetes_prediction.train_model manual__2024-05-01T16:27:46.554638+00:00 [queued]>
[2024-05-01T16:38:29.660+0000] {taskinstance.py:1331} INFO - Starting attempt 2 of 2
[2024-05-01T16:38:29.709+0000] {taskinstance.py:1350} INFO - Executing <Task(PythonOperator): train_model> on 2024-05-01 16:27:46.554638+00:00
[2024-05-01T16:38:29.735+0000] {standard_task_runner.py:57} INFO - Started process 1349 to run task
[2024-05-01T16:38:29.744+0000] {standard_task_runner.py:84} INFO - Running: ['***', 'tasks', 'run', 'diabetes_prediction', 'train_model', 'manual__2024-05-01T16:27:46.554638+00:00', '--job-id', '56', '--raw', '--subdir', 'DAGS_FOLDER/dag1.py', '--cfg-path', '/tmp/tmpn4ewdsbh']
[2024-05-01T16:38:29.749+0000] {standard_task_runner.py:85} INFO - Job 56: Subtask train_model
[2024-05-01T16:38:29.865+0000] {task_command.py:410} INFO - Running <TaskInstance: diabetes_prediction.train_model manual__2024-05-01T16:27:46.554638+00:00 [running]> on host c90068845469
[2024-05-01T16:38:30.118+0000] {taskinstance.py:1570} INFO - Exporting env vars: AIRFLOW_CTX_DAG_OWNER='***' AIRFLOW_CTX_DAG_ID='diabetes_prediction' AIRFLOW_CTX_TASK_ID='train_model' AIRFLOW_CTX_EXECUTION_DATE='2024-05-01T16:27:46.554638+00:00' AIRFLOW_CTX_TRY_NUMBER='2' AIRFLOW_CTX_DAG_RUN_ID='manual__2024-05-01T16:27:46.554638+00:00'
[2024-05-01T16:38:30.632+0000] {logging_mixin.py:149} WARNING - 2024/05/01 16:38:30 WARNING mlflow.utils.git_utils: Failed to import Git (the Git executable is probably not on your PATH), so Git SHA is not available. Error: Failed to initialize: Bad git executable.
The git executable must be specified in one of the following ways:
    - be included in your $PATH
    - be set via $GIT_PYTHON_GIT_EXECUTABLE
    - explicitly set via git.refresh(<full-path-to-git-executable>)

All git commands will error until this is rectified.

This initial message can be silenced or aggravated in the future by setting the
$GIT_PYTHON_REFRESH environment variable. Use one of the following values:
    - quiet|q|silence|s|silent|none|n|0: for no message or exception
    - warn|w|warning|log|l|1: for a warning message (logging level CRITICAL, displayed by default)
    - error|e|exception|raise|r|2: for a raised exception

Example:
    export GIT_PYTHON_REFRESH=quiet
[2024-05-01T16:38:38.138+0000] {warnings.py:110} WARNING - /home/***/.local/lib/python3.7/site-packages/sklearn/linear_model/_logistic.py:818: ConvergenceWarning: lbfgs failed to converge (status=1):
STOP: TOTAL NO. of ITERATIONS REACHED LIMIT.

Increase the number of iterations (max_iter) or scale the data as shown in:
    https://scikit-learn.org/stable/modules/preprocessing.html
Please also refer to the documentation for alternative solver options:
    https://scikit-learn.org/stable/modules/linear_model.html#logistic-regression
  extra_warning_msg=_LOGISTIC_SOLVER_CONVERGENCE_MSG,

[2024-05-01T16:38:38.146+0000] {logging_mixin.py:149} INFO - Accuracy: 0.9959206567742593
[2024-05-01T16:38:44.038+0000] {warnings.py:110} WARNING - /home/***/.local/lib/python3.7/site-packages/_distutils_hack/__init__.py:33: UserWarning: Setuptools is replacing distutils.
  warnings.warn("Setuptools is replacing distutils.")

[2024-05-01T16:38:50.163+0000] {local_task_job_runner.py:299} WARNING - State of this instance has been externally set to failed. Terminating instance.
[2024-05-01T16:38:50.169+0000] {process_utils.py:135} INFO - Sending Signals.SIGTERM to group 1349. PIDs of all processes in the group: [1349]
[2024-05-01T16:38:50.169+0000] {process_utils.py:86} INFO - Sending the signal Signals.SIGTERM to group 1349
[2024-05-01T16:38:50.170+0000] {taskinstance.py:1540} ERROR - Received SIGTERM. Terminating subprocesses.
[2024-05-01T16:38:50.172+0000] {taskinstance.py:1847} ERROR - Task failed with exception
Traceback (most recent call last):
  File "/home/airflow/.local/lib/python3.7/site-packages/mlflow/utils/rest_utils.py", line 175, in http_request
    **kwargs,
  File "/home/airflow/.local/lib/python3.7/site-packages/mlflow/utils/rest_utils.py", line 97, in _get_http_response_with_retries
    return session.request(method, url, **kwargs)
  File "/home/airflow/.local/lib/python3.7/site-packages/requests/sessions.py", line 587, in request
    resp = self.send(prep, **send_kwargs)
  File "/home/airflow/.local/lib/python3.7/site-packages/requests/sessions.py", line 701, in send
    r = adapter.send(request, **kwargs)
  File "/home/airflow/.local/lib/python3.7/site-packages/requests/adapters.py", line 498, in send
    chunked=chunked,
  File "/home/airflow/.local/lib/python3.7/site-packages/urllib3/connectionpool.py", line 891, in urlopen
    **response_kw
  File "/home/airflow/.local/lib/python3.7/site-packages/urllib3/connectionpool.py", line 891, in urlopen
    **response_kw
  File "/home/airflow/.local/lib/python3.7/site-packages/urllib3/connectionpool.py", line 876, in urlopen
    retries.sleep(response)
  File "/home/airflow/.local/lib/python3.7/site-packages/urllib3/util/retry.py", line 432, in sleep
    self._sleep_backoff()
  File "/home/airflow/.local/lib/python3.7/site-packages/urllib3/util/retry.py", line 416, in _sleep_backoff
    time.sleep(backoff)
  File "/home/airflow/.local/lib/python3.7/site-packages/airflow/models/taskinstance.py", line 1542, in signal_handler
    raise AirflowException("Task received SIGTERM signal")
airflow.exceptions.AirflowException: Task received SIGTERM signal

During handling of the above exception, another exception occurred:

Traceback (most recent call last):
  File "/home/airflow/.local/lib/python3.7/site-packages/airflow/operators/python.py", line 181, in execute
    return_value = self.execute_callable()
  File "/home/airflow/.local/lib/python3.7/site-packages/airflow/operators/python.py", line 198, in execute_callable
    return self.python_callable(*self.op_args, **self.op_kwargs)
  File "/opt/airflow/dags/dag1.py", line 67, in train_model
    mlflow.sklearn.log_model(logistic_classifier, "LogisticRegression")
  File "/home/airflow/.local/lib/python3.7/site-packages/mlflow/sklearn/__init__.py", line 420, in log_model
    pyfunc_predict_fn=pyfunc_predict_fn,
  File "/home/airflow/.local/lib/python3.7/site-packages/mlflow/models/model.py", line 374, in log
    mlflow.tracking.fluent.log_artifacts(local_path, mlflow_model.artifact_path)
  File "/home/airflow/.local/lib/python3.7/site-packages/mlflow/tracking/fluent.py", line 813, in log_artifacts
    MlflowClient().log_artifacts(run_id, local_dir, artifact_path)
  File "/home/airflow/.local/lib/python3.7/site-packages/mlflow/tracking/client.py", line 1182, in log_artifacts
    self._tracking_client.log_artifacts(run_id, local_dir, artifact_path)
  File "/home/airflow/.local/lib/python3.7/site-packages/mlflow/tracking/_tracking_service/client.py", line 469, in log_artifacts
    self._get_artifact_repo(run_id).log_artifacts(local_dir, artifact_path)
  File "/home/airflow/.local/lib/python3.7/site-packages/mlflow/store/artifact/http_artifact_repo.py", line 40, in log_artifacts
    self.log_artifact(os.path.join(root, f), artifact_dir)
  File "/home/airflow/.local/lib/python3.7/site-packages/mlflow/store/artifact/http_artifact_repo.py", line 25, in log_artifact
    resp = http_request(self._host_creds, endpoint, "PUT", data=f)
  File "/home/airflow/.local/lib/python3.7/site-packages/mlflow/utils/rest_utils.py", line 184, in http_request
    raise MlflowException("API request to %s failed with exception %s" % (url, e))
mlflow.exceptions.MlflowException: API request to http://mlflow:1880/api/2.0/mlflow-artifacts/artifacts/0/63168542a31e4ad7bd00aea00ac5f422/artifacts/LogisticRegression/MLmodel failed with exception Task received SIGTERM signal
[2024-05-01T16:38:50.216+0000] {taskinstance.py:1373} INFO - Marking task as FAILED. dag_id=diabetes_prediction, task_id=train_model, execution_date=20240501T162746, start_date=20240501T163829, end_date=20240501T163850
[2024-05-01T16:38:50.253+0000] {standard_task_runner.py:109} ERROR - Failed to execute job 56 for task train_model (API request to http://mlflow:1880/api/2.0/mlflow-artifacts/artifacts/0/63168542a31e4ad7bd00aea00ac5f422/artifacts/LogisticRegression/MLmodel failed with exception Task received SIGTERM signal; 1349)
[2024-05-01T16:38:50.305+0000] {process_utils.py:79} INFO - Process psutil.Process(pid=1349, status='terminated', exitcode=1, started='16:38:29') (1349) terminated with exit code 1
