[2024-05-01T15:43:31.016+0000] {taskinstance.py:1125} INFO - Dependencies all met for dep_context=non-requeueable deps ti=<TaskInstance: json_to_dataframe_and_train_model.load_and_transform_task manual__2024-05-01T15:31:15.326075+00:00 [queued]>
[2024-05-01T15:43:31.343+0000] {taskinstance.py:1125} INFO - Dependencies all met for dep_context=requeueable deps ti=<TaskInstance: json_to_dataframe_and_train_model.load_and_transform_task manual__2024-05-01T15:31:15.326075+00:00 [queued]>
[2024-05-01T15:43:31.344+0000] {taskinstance.py:1331} INFO - Starting attempt 1 of 2
[2024-05-01T15:43:32.328+0000] {taskinstance.py:1350} INFO - Executing <Task(PythonOperator): load_and_transform_task> on 2024-05-01 15:31:15.326075+00:00
[2024-05-01T15:43:32.575+0000] {standard_task_runner.py:57} INFO - Started process 108 to run task
[2024-05-01T15:43:32.624+0000] {standard_task_runner.py:84} INFO - Running: ['***', 'tasks', 'run', 'json_to_dataframe_and_train_model', 'load_and_transform_task', 'manual__2024-05-01T15:31:15.326075+00:00', '--job-id', '18', '--raw', '--subdir', 'DAGS_FOLDER/dag2.py', '--cfg-path', '/tmp/tmp8djvakww']
[2024-05-01T15:43:32.691+0000] {standard_task_runner.py:85} INFO - Job 18: Subtask load_and_transform_task
[2024-05-01T15:43:34.008+0000] {task_command.py:410} INFO - Running <TaskInstance: json_to_dataframe_and_train_model.load_and_transform_task manual__2024-05-01T15:31:15.326075+00:00 [running]> on host c90068845469
[2024-05-01T15:43:35.798+0000] {taskinstance.py:1570} INFO - Exporting env vars: AIRFLOW_CTX_DAG_OWNER='***' AIRFLOW_CTX_DAG_ID='json_to_dataframe_and_train_model' AIRFLOW_CTX_TASK_ID='load_and_transform_task' AIRFLOW_CTX_EXECUTION_DATE='2024-05-01T15:31:15.326075+00:00' AIRFLOW_CTX_TRY_NUMBER='1' AIRFLOW_CTX_DAG_RUN_ID='manual__2024-05-01T15:31:15.326075+00:00'
[2024-05-01T15:43:35.830+0000] {taskinstance.py:1847} ERROR - Task failed with exception
Traceback (most recent call last):
  File "/home/airflow/.local/lib/python3.7/site-packages/airflow/operators/python.py", line 181, in execute
    return_value = self.execute_callable()
  File "/home/airflow/.local/lib/python3.7/site-packages/airflow/operators/python.py", line 198, in execute_callable
    return self.python_callable(*self.op_args, **self.op_kwargs)
  File "/opt/airflow/dags/dag2.py", line 33, in load_and_transform_data
    with open(json_file_path, 'r') as f:
FileNotFoundError: [Errno 2] No such file or directory: '/opt/airflow/data/collected_data.json'
[2024-05-01T15:43:36.006+0000] {taskinstance.py:1373} INFO - Marking task as UP_FOR_RETRY. dag_id=json_to_dataframe_and_train_model, task_id=load_and_transform_task, execution_date=20240501T153115, start_date=20240501T154331, end_date=20240501T154335
[2024-05-01T15:43:37.211+0000] {standard_task_runner.py:109} ERROR - Failed to execute job 18 for task load_and_transform_task ([Errno 2] No such file or directory: '/opt/airflow/data/collected_data.json'; 108)
[2024-05-01T15:43:37.387+0000] {local_task_job_runner.py:232} INFO - Task exited with return code 1
[2024-05-01T15:43:37.835+0000] {taskinstance.py:2674} INFO - 0 downstream tasks scheduled from follow-on schedule check
