[2024-05-03T01:52:21.087+0000] {taskinstance.py:1125} INFO - Dependencies all met for dep_context=non-requeueable deps ti=<TaskInstance: diabetes_prediction.train_model manual__2024-05-03T01:52:04.463332+00:00 [queued]>
[2024-05-03T01:52:21.109+0000] {taskinstance.py:1125} INFO - Dependencies all met for dep_context=requeueable deps ti=<TaskInstance: diabetes_prediction.train_model manual__2024-05-03T01:52:04.463332+00:00 [queued]>
[2024-05-03T01:52:21.109+0000] {taskinstance.py:1331} INFO - Starting attempt 1 of 2
[2024-05-03T01:52:21.135+0000] {taskinstance.py:1350} INFO - Executing <Task(PythonOperator): train_model> on 2024-05-03 01:52:04.463332+00:00
[2024-05-03T01:52:21.150+0000] {standard_task_runner.py:57} INFO - Started process 3636 to run task
[2024-05-03T01:52:21.158+0000] {standard_task_runner.py:84} INFO - Running: ['***', 'tasks', 'run', 'diabetes_prediction', 'train_model', 'manual__2024-05-03T01:52:04.463332+00:00', '--job-id', '241', '--raw', '--subdir', 'DAGS_FOLDER/dag1.py', '--cfg-path', '/tmp/tmpf04gw_hd']
[2024-05-03T01:52:21.159+0000] {standard_task_runner.py:85} INFO - Job 241: Subtask train_model
[2024-05-03T01:52:21.248+0000] {task_command.py:410} INFO - Running <TaskInstance: diabetes_prediction.train_model manual__2024-05-03T01:52:04.463332+00:00 [running]> on host 9218b8cabb2d
[2024-05-03T01:52:21.412+0000] {taskinstance.py:1570} INFO - Exporting env vars: AIRFLOW_CTX_DAG_OWNER='***' AIRFLOW_CTX_DAG_ID='diabetes_prediction' AIRFLOW_CTX_TASK_ID='train_model' AIRFLOW_CTX_EXECUTION_DATE='2024-05-03T01:52:04.463332+00:00' AIRFLOW_CTX_TRY_NUMBER='1' AIRFLOW_CTX_DAG_RUN_ID='manual__2024-05-03T01:52:04.463332+00:00'
[2024-05-03T01:52:22.311+0000] {logging_mixin.py:149} WARNING - 2024/05/03 01:52:22 WARNING mlflow.utils.git_utils: Failed to import Git (the Git executable is probably not on your PATH), so Git SHA is not available. Error: Failed to initialize: Bad git executable.
The git executable must be specified in one of the following ways:
    - be included in your $PATH
    - be set via $GIT_PYTHON_GIT_EXECUTABLE
    - explicitly set via git.refresh(<full-path-to-git-executable>)

All git commands will error until this is rectified.

This initial message can be silenced or aggravated in the future by setting the
$GIT_PYTHON_REFRESH environment variable. Use one of the following values:
    - quiet|q|silence|s|silent|none|n|0: for no message or exception
    - warn|w|warning|log|l|1: for a warning message (logging level CRITICAL, displayed by default)
    - error|e|exception|raise|r|2: for a raised exception

Example:
    export GIT_PYTHON_REFRESH=quiet
[2024-05-03T01:52:27.582+0000] {logging_and_warnings.py:72} WARNING - /home/***/.local/lib/python3.7/site-packages/sklearn/linear_model/_logistic.py:818: ConvergenceWarning: lbfgs failed to converge (status=1):
STOP: TOTAL NO. of ITERATIONS REACHED LIMIT.

Increase the number of iterations (max_iter) or scale the data as shown in:
    https://scikit-learn.org/stable/modules/preprocessing.html
Please also refer to the documentation for alternative solver options:
    https://scikit-learn.org/stable/modules/linear_model.html#logistic-regression
  extra_warning_msg=_LOGISTIC_SOLVER_CONVERGENCE_MSG,

[2024-05-03T01:52:27.871+0000] {logging_mixin.py:149} WARNING - 2024/05/03 01:52:27 WARNING mlflow.sklearn.utils: Failed to import matplotlib (error: ModuleNotFoundError("No module named 'matplotlib'")). Skipping artifact logging.
[2024-05-03T01:52:27.945+0000] {logging_mixin.py:149} WARNING - 2024/05/03 01:52:27 WARNING mlflow.utils.autologging_utils: MLflow autologging encountered a warning: "/home/***/.local/lib/python3.7/site-packages/mlflow/models/signature.py:129: UserWarning: Hint: Inferred schema contains integer column(s). Integer columns in Python cannot represent missing values. If your input data contains missing values at inference time, it will be encoded as floats and will cause a schema enforcement error. The best way to avoid this problem is to infer the model schema based on a realistic data sample (training dataset) that includes missing values. Alternatively, you can declare integer columns as doubles (float64) whenever these columns may have missing values. See `Handling Integers With Missing Values <https://www.mlflow.org/docs/latest/models.html#handling-integers-with-missing-values>`_ for more details."
[2024-05-03T01:52:33.969+0000] {logging_mixin.py:149} WARNING - 2024/05/03 01:52:33 WARNING mlflow.utils.autologging_utils: MLflow autologging encountered a warning: "/home/***/.local/lib/python3.7/site-packages/_distutils_hack/__init__.py:33: UserWarning: Setuptools is replacing distutils."
[2024-05-03T01:52:34.156+0000] {taskinstance.py:1847} ERROR - Task failed with exception
Traceback (most recent call last):
  File "/home/airflow/.local/lib/python3.7/site-packages/airflow/operators/python.py", line 181, in execute
    return_value = self.execute_callable()
  File "/home/airflow/.local/lib/python3.7/site-packages/airflow/operators/python.py", line 198, in execute_callable
    return self.python_callable(*self.op_args, **self.op_kwargs)
  File "/opt/airflow/dags/dag1.py", line 49, in train_model
    mlflow.log_model(logistic_classifier, "DiabetesLogisticRegressionModel")
AttributeError: module 'mlflow' has no attribute 'log_model'
[2024-05-03T01:52:34.183+0000] {taskinstance.py:1373} INFO - Marking task as UP_FOR_RETRY. dag_id=diabetes_prediction, task_id=train_model, execution_date=20240503T015204, start_date=20240503T015221, end_date=20240503T015234
[2024-05-03T01:52:34.241+0000] {standard_task_runner.py:109} ERROR - Failed to execute job 241 for task train_model (module 'mlflow' has no attribute 'log_model'; 3636)
[2024-05-03T01:52:34.306+0000] {local_task_job_runner.py:232} INFO - Task exited with return code 1
[2024-05-03T01:52:34.394+0000] {taskinstance.py:2674} INFO - 0 downstream tasks scheduled from follow-on schedule check
