[2024-05-01T16:38:05.236+0000] {taskinstance.py:1125} INFO - Dependencies all met for dep_context=non-requeueable deps ti=<TaskInstance: diabetes_prediction.train_model manual__2024-05-01T16:37:36.891971+00:00 [queued]>
[2024-05-01T16:38:05.263+0000] {taskinstance.py:1125} INFO - Dependencies all met for dep_context=requeueable deps ti=<TaskInstance: diabetes_prediction.train_model manual__2024-05-01T16:37:36.891971+00:00 [queued]>
[2024-05-01T16:38:05.263+0000] {taskinstance.py:1331} INFO - Starting attempt 1 of 2
[2024-05-01T16:38:05.307+0000] {taskinstance.py:1350} INFO - Executing <Task(PythonOperator): train_model> on 2024-05-01 16:37:36.891971+00:00
[2024-05-01T16:38:05.326+0000] {standard_task_runner.py:57} INFO - Started process 1326 to run task
[2024-05-01T16:38:05.356+0000] {standard_task_runner.py:84} INFO - Running: ['***', 'tasks', 'run', 'diabetes_prediction', 'train_model', 'manual__2024-05-01T16:37:36.891971+00:00', '--job-id', '55', '--raw', '--subdir', 'DAGS_FOLDER/dag1.py', '--cfg-path', '/tmp/tmp8k3i6lxn']
[2024-05-01T16:38:05.373+0000] {standard_task_runner.py:85} INFO - Job 55: Subtask train_model
[2024-05-01T16:38:05.528+0000] {task_command.py:410} INFO - Running <TaskInstance: diabetes_prediction.train_model manual__2024-05-01T16:37:36.891971+00:00 [running]> on host c90068845469
[2024-05-01T16:38:05.858+0000] {taskinstance.py:1570} INFO - Exporting env vars: AIRFLOW_CTX_DAG_OWNER='***' AIRFLOW_CTX_DAG_ID='diabetes_prediction' AIRFLOW_CTX_TASK_ID='train_model' AIRFLOW_CTX_EXECUTION_DATE='2024-05-01T16:37:36.891971+00:00' AIRFLOW_CTX_TRY_NUMBER='1' AIRFLOW_CTX_DAG_RUN_ID='manual__2024-05-01T16:37:36.891971+00:00'
[2024-05-01T16:38:06.360+0000] {logging_mixin.py:149} WARNING - 2024/05/01 16:38:06 WARNING mlflow.utils.git_utils: Failed to import Git (the Git executable is probably not on your PATH), so Git SHA is not available. Error: Failed to initialize: Bad git executable.
The git executable must be specified in one of the following ways:
    - be included in your $PATH
    - be set via $GIT_PYTHON_GIT_EXECUTABLE
    - explicitly set via git.refresh(<full-path-to-git-executable>)

All git commands will error until this is rectified.

This initial message can be silenced or aggravated in the future by setting the
$GIT_PYTHON_REFRESH environment variable. Use one of the following values:
    - quiet|q|silence|s|silent|none|n|0: for no message or exception
    - warn|w|warning|log|l|1: for a warning message (logging level CRITICAL, displayed by default)
    - error|e|exception|raise|r|2: for a raised exception

Example:
    export GIT_PYTHON_REFRESH=quiet
[2024-05-01T16:38:11.309+0000] {warnings.py:110} WARNING - /home/***/.local/lib/python3.7/site-packages/sklearn/linear_model/_logistic.py:818: ConvergenceWarning: lbfgs failed to converge (status=1):
STOP: TOTAL NO. of ITERATIONS REACHED LIMIT.

Increase the number of iterations (max_iter) or scale the data as shown in:
    https://scikit-learn.org/stable/modules/preprocessing.html
Please also refer to the documentation for alternative solver options:
    https://scikit-learn.org/stable/modules/linear_model.html#logistic-regression
  extra_warning_msg=_LOGISTIC_SOLVER_CONVERGENCE_MSG,

[2024-05-01T16:38:11.319+0000] {logging_mixin.py:149} INFO - Accuracy: 0.9959206567742593
[2024-05-01T16:38:17.446+0000] {warnings.py:110} WARNING - /home/***/.local/lib/python3.7/site-packages/_distutils_hack/__init__.py:33: UserWarning: Setuptools is replacing distutils.
  warnings.warn("Setuptools is replacing distutils.")

[2024-05-01T16:39:19.047+0000] {taskinstance.py:1847} ERROR - Task failed with exception
Traceback (most recent call last):
  File "/home/airflow/.local/lib/python3.7/site-packages/requests/adapters.py", line 498, in send
    chunked=chunked,
  File "/home/airflow/.local/lib/python3.7/site-packages/urllib3/connectionpool.py", line 891, in urlopen
    **response_kw
  File "/home/airflow/.local/lib/python3.7/site-packages/urllib3/connectionpool.py", line 891, in urlopen
    **response_kw
  File "/home/airflow/.local/lib/python3.7/site-packages/urllib3/connectionpool.py", line 891, in urlopen
    **response_kw
  [Previous line repeated 2 more times]
  File "/home/airflow/.local/lib/python3.7/site-packages/urllib3/connectionpool.py", line 868, in urlopen
    retries = retries.increment(method, url, response=response, _pool=self)
  File "/home/airflow/.local/lib/python3.7/site-packages/urllib3/util/retry.py", line 592, in increment
    raise MaxRetryError(_pool, url, error or ResponseError(cause))
urllib3.exceptions.MaxRetryError: HTTPConnectionPool(host='mlflow', port=1880): Max retries exceeded with url: /api/2.0/mlflow-artifacts/artifacts/0/2f60d1bec5114ab1bb22453c55d8b04b/artifacts/LogisticRegression/MLmodel (Caused by ResponseError('too many 500 error responses'))

During handling of the above exception, another exception occurred:

Traceback (most recent call last):
  File "/home/airflow/.local/lib/python3.7/site-packages/mlflow/utils/rest_utils.py", line 175, in http_request
    **kwargs,
  File "/home/airflow/.local/lib/python3.7/site-packages/mlflow/utils/rest_utils.py", line 97, in _get_http_response_with_retries
    return session.request(method, url, **kwargs)
  File "/home/airflow/.local/lib/python3.7/site-packages/requests/sessions.py", line 587, in request
    resp = self.send(prep, **send_kwargs)
  File "/home/airflow/.local/lib/python3.7/site-packages/requests/sessions.py", line 701, in send
    r = adapter.send(request, **kwargs)
  File "/home/airflow/.local/lib/python3.7/site-packages/requests/adapters.py", line 511, in send
    raise RetryError(e, request=request)
requests.exceptions.RetryError: HTTPConnectionPool(host='mlflow', port=1880): Max retries exceeded with url: /api/2.0/mlflow-artifacts/artifacts/0/2f60d1bec5114ab1bb22453c55d8b04b/artifacts/LogisticRegression/MLmodel (Caused by ResponseError('too many 500 error responses'))

During handling of the above exception, another exception occurred:

Traceback (most recent call last):
  File "/home/airflow/.local/lib/python3.7/site-packages/airflow/operators/python.py", line 181, in execute
    return_value = self.execute_callable()
  File "/home/airflow/.local/lib/python3.7/site-packages/airflow/operators/python.py", line 198, in execute_callable
    return self.python_callable(*self.op_args, **self.op_kwargs)
  File "/opt/airflow/dags/dag1.py", line 67, in train_model
    mlflow.sklearn.log_model(logistic_classifier, "LogisticRegression")
  File "/home/airflow/.local/lib/python3.7/site-packages/mlflow/sklearn/__init__.py", line 420, in log_model
    pyfunc_predict_fn=pyfunc_predict_fn,
  File "/home/airflow/.local/lib/python3.7/site-packages/mlflow/models/model.py", line 374, in log
    mlflow.tracking.fluent.log_artifacts(local_path, mlflow_model.artifact_path)
  File "/home/airflow/.local/lib/python3.7/site-packages/mlflow/tracking/fluent.py", line 813, in log_artifacts
    MlflowClient().log_artifacts(run_id, local_dir, artifact_path)
  File "/home/airflow/.local/lib/python3.7/site-packages/mlflow/tracking/client.py", line 1182, in log_artifacts
    self._tracking_client.log_artifacts(run_id, local_dir, artifact_path)
  File "/home/airflow/.local/lib/python3.7/site-packages/mlflow/tracking/_tracking_service/client.py", line 469, in log_artifacts
    self._get_artifact_repo(run_id).log_artifacts(local_dir, artifact_path)
  File "/home/airflow/.local/lib/python3.7/site-packages/mlflow/store/artifact/http_artifact_repo.py", line 40, in log_artifacts
    self.log_artifact(os.path.join(root, f), artifact_dir)
  File "/home/airflow/.local/lib/python3.7/site-packages/mlflow/store/artifact/http_artifact_repo.py", line 25, in log_artifact
    resp = http_request(self._host_creds, endpoint, "PUT", data=f)
  File "/home/airflow/.local/lib/python3.7/site-packages/mlflow/utils/rest_utils.py", line 184, in http_request
    raise MlflowException("API request to %s failed with exception %s" % (url, e))
mlflow.exceptions.MlflowException: API request to http://mlflow:1880/api/2.0/mlflow-artifacts/artifacts/0/2f60d1bec5114ab1bb22453c55d8b04b/artifacts/LogisticRegression/MLmodel failed with exception HTTPConnectionPool(host='mlflow', port=1880): Max retries exceeded with url: /api/2.0/mlflow-artifacts/artifacts/0/2f60d1bec5114ab1bb22453c55d8b04b/artifacts/LogisticRegression/MLmodel (Caused by ResponseError('too many 500 error responses'))
[2024-05-01T16:39:19.092+0000] {taskinstance.py:1373} INFO - Marking task as UP_FOR_RETRY. dag_id=diabetes_prediction, task_id=train_model, execution_date=20240501T163736, start_date=20240501T163805, end_date=20240501T163919
[2024-05-01T16:39:19.147+0000] {standard_task_runner.py:109} ERROR - Failed to execute job 55 for task train_model (API request to http://mlflow:1880/api/2.0/mlflow-artifacts/artifacts/0/2f60d1bec5114ab1bb22453c55d8b04b/artifacts/LogisticRegression/MLmodel failed with exception HTTPConnectionPool(host='mlflow', port=1880): Max retries exceeded with url: /api/2.0/mlflow-artifacts/artifacts/0/2f60d1bec5114ab1bb22453c55d8b04b/artifacts/LogisticRegression/MLmodel (Caused by ResponseError('too many 500 error responses')); 1326)
[2024-05-01T16:39:19.215+0000] {local_task_job_runner.py:232} INFO - Task exited with return code 1
[2024-05-01T16:39:19.306+0000] {taskinstance.py:2674} INFO - 0 downstream tasks scheduled from follow-on schedule check
