[2024-05-02T16:42:26.756+0000] {taskinstance.py:1125} INFO - Dependencies all met for dep_context=non-requeueable deps ti=<TaskInstance: diabetes_prediction.train_model manual__2024-05-02T16:39:38.862043+00:00 [queued]>
[2024-05-02T16:42:26.796+0000] {taskinstance.py:1125} INFO - Dependencies all met for dep_context=requeueable deps ti=<TaskInstance: diabetes_prediction.train_model manual__2024-05-02T16:39:38.862043+00:00 [queued]>
[2024-05-02T16:42:26.796+0000] {taskinstance.py:1331} INFO - Starting attempt 1 of 2
[2024-05-02T16:42:26.850+0000] {taskinstance.py:1350} INFO - Executing <Task(PythonOperator): train_model> on 2024-05-02 16:39:38.862043+00:00
[2024-05-02T16:42:26.867+0000] {standard_task_runner.py:57} INFO - Started process 108 to run task
[2024-05-02T16:42:26.878+0000] {standard_task_runner.py:84} INFO - Running: ['***', 'tasks', 'run', 'diabetes_prediction', 'train_model', 'manual__2024-05-02T16:39:38.862043+00:00', '--job-id', '107', '--raw', '--subdir', 'DAGS_FOLDER/dag1.py', '--cfg-path', '/tmp/tmp2jshhvmo']
[2024-05-02T16:42:26.883+0000] {standard_task_runner.py:85} INFO - Job 107: Subtask train_model
[2024-05-02T16:42:27.076+0000] {task_command.py:410} INFO - Running <TaskInstance: diabetes_prediction.train_model manual__2024-05-02T16:39:38.862043+00:00 [running]> on host 6a7284e02eca
[2024-05-02T16:42:27.456+0000] {taskinstance.py:1570} INFO - Exporting env vars: AIRFLOW_CTX_DAG_OWNER='***' AIRFLOW_CTX_DAG_ID='diabetes_prediction' AIRFLOW_CTX_TASK_ID='train_model' AIRFLOW_CTX_EXECUTION_DATE='2024-05-02T16:39:38.862043+00:00' AIRFLOW_CTX_TRY_NUMBER='1' AIRFLOW_CTX_DAG_RUN_ID='manual__2024-05-02T16:39:38.862043+00:00'
[2024-05-02T16:42:28.399+0000] {logging_mixin.py:149} WARNING - 2024/05/02 16:42:28 WARNING mlflow.utils.git_utils: Failed to import Git (the Git executable is probably not on your PATH), so Git SHA is not available. Error: Failed to initialize: Bad git executable.
The git executable must be specified in one of the following ways:
    - be included in your $PATH
    - be set via $GIT_PYTHON_GIT_EXECUTABLE
    - explicitly set via git.refresh(<full-path-to-git-executable>)

All git commands will error until this is rectified.

This initial message can be silenced or aggravated in the future by setting the
$GIT_PYTHON_REFRESH environment variable. Use one of the following values:
    - quiet|q|silence|s|silent|none|n|0: for no message or exception
    - warn|w|warning|log|l|1: for a warning message (logging level CRITICAL, displayed by default)
    - error|e|exception|raise|r|2: for a raised exception

Example:
    export GIT_PYTHON_REFRESH=quiet
[2024-05-02T16:42:45.152+0000] {logging_and_warnings.py:72} WARNING - /home/***/.local/lib/python3.7/site-packages/sklearn/linear_model/_logistic.py:818: ConvergenceWarning: lbfgs failed to converge (status=1):
STOP: TOTAL NO. of ITERATIONS REACHED LIMIT.

Increase the number of iterations (max_iter) or scale the data as shown in:
    https://scikit-learn.org/stable/modules/preprocessing.html
Please also refer to the documentation for alternative solver options:
    https://scikit-learn.org/stable/modules/linear_model.html#logistic-regression
  extra_warning_msg=_LOGISTIC_SOLVER_CONVERGENCE_MSG,

[2024-05-02T16:42:45.660+0000] {logging_mixin.py:149} WARNING - 2024/05/02 16:42:45 WARNING mlflow.sklearn.utils: Failed to import matplotlib (error: ModuleNotFoundError("No module named 'matplotlib'")). Skipping artifact logging.
[2024-05-02T16:43:46.976+0000] {logging_mixin.py:149} WARNING - 2024/05/02 16:43:46 WARNING mlflow.utils.autologging_utils: Encountered unexpected error during sklearn autologging: API request to http://mlflow:1880/api/2.0/mlflow-artifacts/artifacts/0/cc06f0fd732d40219334e7862c2996d6/artifacts/estimator.html failed with exception HTTPConnectionPool(host='mlflow', port=1880): Max retries exceeded with url: /api/2.0/mlflow-artifacts/artifacts/0/cc06f0fd732d40219334e7862c2996d6/artifacts/estimator.html (Caused by ResponseError('too many 500 error responses'))
[2024-05-02T16:43:52.995+0000] {warnings.py:110} WARNING - /home/***/.local/lib/python3.7/site-packages/_distutils_hack/__init__.py:33: UserWarning: Setuptools is replacing distutils.
  warnings.warn("Setuptools is replacing distutils.")

