[2024-05-03T00:05:46.819+0000] {taskinstance.py:1125} INFO - Dependencies all met for dep_context=non-requeueable deps ti=<TaskInstance: diabetes_prediction.train_model scheduled__2024-05-02T00:00:00+00:00 [queued]>
[2024-05-03T00:05:46.854+0000] {taskinstance.py:1125} INFO - Dependencies all met for dep_context=requeueable deps ti=<TaskInstance: diabetes_prediction.train_model scheduled__2024-05-02T00:00:00+00:00 [queued]>
[2024-05-03T00:05:46.854+0000] {taskinstance.py:1331} INFO - Starting attempt 2 of 2
[2024-05-03T00:05:46.895+0000] {taskinstance.py:1350} INFO - Executing <Task(PythonOperator): train_model> on 2024-05-02 00:00:00+00:00
[2024-05-03T00:05:46.919+0000] {standard_task_runner.py:57} INFO - Started process 1713 to run task
[2024-05-03T00:05:46.928+0000] {standard_task_runner.py:84} INFO - Running: ['***', 'tasks', 'run', 'diabetes_prediction', 'train_model', 'scheduled__2024-05-02T00:00:00+00:00', '--job-id', '226', '--raw', '--subdir', 'DAGS_FOLDER/dag1.py', '--cfg-path', '/tmp/tmph_3f8ivp']
[2024-05-03T00:05:46.935+0000] {standard_task_runner.py:85} INFO - Job 226: Subtask train_model
[2024-05-03T00:05:47.092+0000] {task_command.py:410} INFO - Running <TaskInstance: diabetes_prediction.train_model scheduled__2024-05-02T00:00:00+00:00 [running]> on host 9218b8cabb2d
[2024-05-03T00:05:47.374+0000] {taskinstance.py:1570} INFO - Exporting env vars: AIRFLOW_CTX_DAG_OWNER='***' AIRFLOW_CTX_DAG_ID='diabetes_prediction' AIRFLOW_CTX_TASK_ID='train_model' AIRFLOW_CTX_EXECUTION_DATE='2024-05-02T00:00:00+00:00' AIRFLOW_CTX_TRY_NUMBER='2' AIRFLOW_CTX_DAG_RUN_ID='scheduled__2024-05-02T00:00:00+00:00'
[2024-05-03T00:05:48.287+0000] {logging_mixin.py:149} WARNING - 2024/05/03 00:05:48 WARNING mlflow.utils.git_utils: Failed to import Git (the Git executable is probably not on your PATH), so Git SHA is not available. Error: Failed to initialize: Bad git executable.
The git executable must be specified in one of the following ways:
    - be included in your $PATH
    - be set via $GIT_PYTHON_GIT_EXECUTABLE
    - explicitly set via git.refresh(<full-path-to-git-executable>)

All git commands will error until this is rectified.

This initial message can be silenced or aggravated in the future by setting the
$GIT_PYTHON_REFRESH environment variable. Use one of the following values:
    - quiet|q|silence|s|silent|none|n|0: for no message or exception
    - warn|w|warning|log|l|1: for a warning message (logging level CRITICAL, displayed by default)
    - error|e|exception|raise|r|2: for a raised exception

Example:
    export GIT_PYTHON_REFRESH=quiet
[2024-05-03T00:05:52.962+0000] {logging_and_warnings.py:72} WARNING - /home/***/.local/lib/python3.7/site-packages/sklearn/linear_model/_logistic.py:818: ConvergenceWarning: lbfgs failed to converge (status=1):
STOP: TOTAL NO. of ITERATIONS REACHED LIMIT.

Increase the number of iterations (max_iter) or scale the data as shown in:
    https://scikit-learn.org/stable/modules/preprocessing.html
Please also refer to the documentation for alternative solver options:
    https://scikit-learn.org/stable/modules/linear_model.html#logistic-regression
  extra_warning_msg=_LOGISTIC_SOLVER_CONVERGENCE_MSG,

[2024-05-03T00:05:53.328+0000] {logging_mixin.py:149} WARNING - 2024/05/03 00:05:53 WARNING mlflow.sklearn.utils: Failed to import matplotlib (error: ModuleNotFoundError("No module named 'matplotlib'")). Skipping artifact logging.
[2024-05-03T00:05:53.405+0000] {logging_mixin.py:149} WARNING - 2024/05/03 00:05:53 WARNING mlflow.utils.autologging_utils: MLflow autologging encountered a warning: "/home/***/.local/lib/python3.7/site-packages/mlflow/models/signature.py:129: UserWarning: Hint: Inferred schema contains integer column(s). Integer columns in Python cannot represent missing values. If your input data contains missing values at inference time, it will be encoded as floats and will cause a schema enforcement error. The best way to avoid this problem is to infer the model schema based on a realistic data sample (training dataset) that includes missing values. Alternatively, you can declare integer columns as doubles (float64) whenever these columns may have missing values. See `Handling Integers With Missing Values <https://www.mlflow.org/docs/latest/models.html#handling-integers-with-missing-values>`_ for more details."
[2024-05-03T00:05:59.585+0000] {logging_mixin.py:149} WARNING - 2024/05/03 00:05:59 WARNING mlflow.utils.autologging_utils: MLflow autologging encountered a warning: "/home/***/.local/lib/python3.7/site-packages/_distutils_hack/__init__.py:33: UserWarning: Setuptools is replacing distutils."
[2024-05-03T00:06:04.413+0000] {taskinstance.py:1847} ERROR - Task failed with exception
Traceback (most recent call last):
  File "/home/airflow/.local/lib/python3.7/site-packages/airflow/operators/python.py", line 181, in execute
    return_value = self.execute_callable()
  File "/home/airflow/.local/lib/python3.7/site-packages/airflow/operators/python.py", line 198, in execute_callable
    return self.python_callable(*self.op_args, **self.op_kwargs)
  File "/opt/airflow/dags/dag1.py", line 59, in train_model
    mlflow.register_model(model_uri, "RandomForestModel")
  File "/home/airflow/.local/lib/python3.7/site-packages/mlflow/tracking/_model_registry/fluent.py", line 74, in register_model
    raise e
  File "/home/airflow/.local/lib/python3.7/site-packages/mlflow/tracking/_model_registry/fluent.py", line 65, in register_model
    create_model_response = client.create_registered_model(name)
  File "/home/airflow/.local/lib/python3.7/site-packages/mlflow/tracking/client.py", line 1847, in create_registered_model
    return self._get_registry_client().create_registered_model(name, tags, description)
  File "/home/airflow/.local/lib/python3.7/site-packages/mlflow/tracking/_model_registry/client.py", line 59, in create_registered_model
    return self.store.create_registered_model(name, tags, description)
  File "/home/airflow/.local/lib/python3.7/site-packages/mlflow/store/model_registry/rest_store.py", line 83, in create_registered_model
    response_proto = self._call_endpoint(CreateRegisteredModel, req_body)
  File "/home/airflow/.local/lib/python3.7/site-packages/mlflow/store/model_registry/rest_store.py", line 64, in _call_endpoint
    return call_endpoint(self.get_host_creds(), endpoint, method, json_body, response_proto)
  File "/home/airflow/.local/lib/python3.7/site-packages/mlflow/utils/rest_utils.py", line 280, in call_endpoint
    response = verify_rest_response(response, endpoint)
  File "/home/airflow/.local/lib/python3.7/site-packages/mlflow/utils/rest_utils.py", line 214, in verify_rest_response
    error_code=get_error_code(response.status_code),
mlflow.exceptions.MlflowException: API request to endpoint /api/2.0/preview/mlflow/registered-models/create failed with error code 404 != 200. Response body: '<!doctype html>
<html lang=en>
<title>404 Not Found</title>
<h1>Not Found</h1>
<p>The requested URL was not found on the server. If you entered the URL manually please check your spelling and try again.</p>
'
[2024-05-03T00:06:04.467+0000] {taskinstance.py:1373} INFO - Marking task as FAILED. dag_id=diabetes_prediction, task_id=train_model, execution_date=20240502T000000, start_date=20240503T000546, end_date=20240503T000604
[2024-05-03T00:06:04.528+0000] {standard_task_runner.py:109} ERROR - Failed to execute job 226 for task train_model (API request to endpoint /api/2.0/preview/mlflow/registered-models/create failed with error code 404 != 200. Response body: '<!doctype html>
<html lang=en>
<title>404 Not Found</title>
<h1>Not Found</h1>
<p>The requested URL was not found on the server. If you entered the URL manually please check your spelling and try again.</p>
'; 1713)
[2024-05-03T00:06:04.591+0000] {local_task_job_runner.py:232} INFO - Task exited with return code 1
[2024-05-03T00:06:04.658+0000] {taskinstance.py:2674} INFO - 0 downstream tasks scheduled from follow-on schedule check
