[2024-05-01T16:52:37.842+0000] {taskinstance.py:1125} INFO - Dependencies all met for dep_context=non-requeueable deps ti=<TaskInstance: diabetes_prediction.train_model manual__2024-05-01T16:52:18.941880+00:00 [queued]>
[2024-05-01T16:52:37.867+0000] {taskinstance.py:1125} INFO - Dependencies all met for dep_context=requeueable deps ti=<TaskInstance: diabetes_prediction.train_model manual__2024-05-01T16:52:18.941880+00:00 [queued]>
[2024-05-01T16:52:37.868+0000] {taskinstance.py:1331} INFO - Starting attempt 1 of 2
[2024-05-01T16:52:37.901+0000] {taskinstance.py:1350} INFO - Executing <Task(PythonOperator): train_model> on 2024-05-01 16:52:18.941880+00:00
[2024-05-01T16:52:37.922+0000] {standard_task_runner.py:57} INFO - Started process 1669 to run task
[2024-05-01T16:52:37.931+0000] {standard_task_runner.py:84} INFO - Running: ['***', 'tasks', 'run', 'diabetes_prediction', 'train_model', 'manual__2024-05-01T16:52:18.941880+00:00', '--job-id', '61', '--raw', '--subdir', 'DAGS_FOLDER/dag1.py', '--cfg-path', '/tmp/tmp0udfbo_i']
[2024-05-01T16:52:37.935+0000] {standard_task_runner.py:85} INFO - Job 61: Subtask train_model
[2024-05-01T16:52:38.059+0000] {task_command.py:410} INFO - Running <TaskInstance: diabetes_prediction.train_model manual__2024-05-01T16:52:18.941880+00:00 [running]> on host c90068845469
[2024-05-01T16:52:38.338+0000] {taskinstance.py:1570} INFO - Exporting env vars: AIRFLOW_CTX_DAG_OWNER='***' AIRFLOW_CTX_DAG_ID='diabetes_prediction' AIRFLOW_CTX_TASK_ID='train_model' AIRFLOW_CTX_EXECUTION_DATE='2024-05-01T16:52:18.941880+00:00' AIRFLOW_CTX_TRY_NUMBER='1' AIRFLOW_CTX_DAG_RUN_ID='manual__2024-05-01T16:52:18.941880+00:00'
[2024-05-01T16:52:38.804+0000] {logging_mixin.py:149} WARNING - 2024/05/01 16:52:38 INFO mlflow.tracking.fluent: Experiment with name 'mlflow_tracking_multiclass_model' does not exist. Creating a new experiment.
[2024-05-01T16:52:40.262+0000] {logging_mixin.py:149} WARNING - 2024/05/01 16:52:40 INFO mlflow.tracking.fluent: Autologging successfully enabled for sklearn.
[2024-05-01T16:52:40.399+0000] {logging_mixin.py:149} WARNING - 2024/05/01 16:52:40 WARNING mlflow.utils.git_utils: Failed to import Git (the Git executable is probably not on your PATH), so Git SHA is not available. Error: Failed to initialize: Bad git executable.
The git executable must be specified in one of the following ways:
    - be included in your $PATH
    - be set via $GIT_PYTHON_GIT_EXECUTABLE
    - explicitly set via git.refresh(<full-path-to-git-executable>)

All git commands will error until this is rectified.

This initial message can be silenced or aggravated in the future by setting the
$GIT_PYTHON_REFRESH environment variable. Use one of the following values:
    - quiet|q|silence|s|silent|none|n|0: for no message or exception
    - warn|w|warning|log|l|1: for a warning message (logging level CRITICAL, displayed by default)
    - error|e|exception|raise|r|2: for a raised exception

Example:
    export GIT_PYTHON_REFRESH=quiet
[2024-05-01T16:52:46.884+0000] {logging_and_warnings.py:72} WARNING - /home/***/.local/lib/python3.7/site-packages/sklearn/linear_model/_logistic.py:818: ConvergenceWarning: lbfgs failed to converge (status=1):
STOP: TOTAL NO. of ITERATIONS REACHED LIMIT.

Increase the number of iterations (max_iter) or scale the data as shown in:
    https://scikit-learn.org/stable/modules/preprocessing.html
Please also refer to the documentation for alternative solver options:
    https://scikit-learn.org/stable/modules/linear_model.html#logistic-regression
  extra_warning_msg=_LOGISTIC_SOLVER_CONVERGENCE_MSG,

[2024-05-01T16:52:47.294+0000] {logging_mixin.py:149} WARNING - 2024/05/01 16:52:47 WARNING mlflow.sklearn.utils: Failed to import matplotlib (error: ModuleNotFoundError("No module named 'matplotlib'")). Skipping artifact logging.
[2024-05-01T16:53:47.769+0000] {logging_mixin.py:149} WARNING - 2024/05/01 16:53:47 WARNING mlflow.utils.autologging_utils: Encountered unexpected error during sklearn autologging: API request to http://mlflow:1880/api/2.0/mlflow-artifacts/artifacts/1/fffb99c9fbaf4c2cb1118bb3732c3b8d/artifacts/estimator.html failed with exception HTTPConnectionPool(host='mlflow', port=1880): Max retries exceeded with url: /api/2.0/mlflow-artifacts/artifacts/1/fffb99c9fbaf4c2cb1118bb3732c3b8d/artifacts/estimator.html (Caused by ResponseError('too many 500 error responses'))
[2024-05-01T16:53:47.769+0000] {python.py:183} INFO - Done. Returned value was: None
[2024-05-01T16:53:47.800+0000] {taskinstance.py:1373} INFO - Marking task as SUCCESS. dag_id=diabetes_prediction, task_id=train_model, execution_date=20240501T165218, start_date=20240501T165237, end_date=20240501T165347
[2024-05-01T16:53:47.895+0000] {local_task_job_runner.py:232} INFO - Task exited with return code 0
[2024-05-01T16:53:47.953+0000] {taskinstance.py:2674} INFO - 0 downstream tasks scheduled from follow-on schedule check
