[2024-05-02T20:25:28.128+0000] {taskinstance.py:1125} INFO - Dependencies all met for dep_context=non-requeueable deps ti=<TaskInstance: diabetes_prediction.train_model manual__2024-05-02T20:25:04.560889+00:00 [queued]>
[2024-05-02T20:25:28.193+0000] {taskinstance.py:1125} INFO - Dependencies all met for dep_context=requeueable deps ti=<TaskInstance: diabetes_prediction.train_model manual__2024-05-02T20:25:04.560889+00:00 [queued]>
[2024-05-02T20:25:28.194+0000] {taskinstance.py:1331} INFO - Starting attempt 1 of 2
[2024-05-02T20:25:28.264+0000] {taskinstance.py:1350} INFO - Executing <Task(PythonOperator): train_model> on 2024-05-02 20:25:04.560889+00:00
[2024-05-02T20:25:28.304+0000] {standard_task_runner.py:57} INFO - Started process 144 to run task
[2024-05-02T20:25:28.321+0000] {standard_task_runner.py:84} INFO - Running: ['***', 'tasks', 'run', 'diabetes_prediction', 'train_model', 'manual__2024-05-02T20:25:04.560889+00:00', '--job-id', '145', '--raw', '--subdir', 'DAGS_FOLDER/dag1.py', '--cfg-path', '/tmp/tmpfx00lfni']
[2024-05-02T20:25:28.328+0000] {standard_task_runner.py:85} INFO - Job 145: Subtask train_model
[2024-05-02T20:25:28.516+0000] {task_command.py:410} INFO - Running <TaskInstance: diabetes_prediction.train_model manual__2024-05-02T20:25:04.560889+00:00 [running]> on host 1b5b5243d6d1
[2024-05-02T20:25:28.902+0000] {taskinstance.py:1570} INFO - Exporting env vars: AIRFLOW_CTX_DAG_OWNER='***' AIRFLOW_CTX_DAG_ID='diabetes_prediction' AIRFLOW_CTX_TASK_ID='train_model' AIRFLOW_CTX_EXECUTION_DATE='2024-05-02T20:25:04.560889+00:00' AIRFLOW_CTX_TRY_NUMBER='1' AIRFLOW_CTX_DAG_RUN_ID='manual__2024-05-02T20:25:04.560889+00:00'
[2024-05-02T20:25:29.994+0000] {logging_mixin.py:149} WARNING - 2024/05/02 20:25:29 WARNING mlflow.utils.git_utils: Failed to import Git (the Git executable is probably not on your PATH), so Git SHA is not available. Error: Failed to initialize: Bad git executable.
The git executable must be specified in one of the following ways:
    - be included in your $PATH
    - be set via $GIT_PYTHON_GIT_EXECUTABLE
    - explicitly set via git.refresh(<full-path-to-git-executable>)

All git commands will error until this is rectified.

This initial message can be silenced or aggravated in the future by setting the
$GIT_PYTHON_REFRESH environment variable. Use one of the following values:
    - quiet|q|silence|s|silent|none|n|0: for no message or exception
    - warn|w|warning|log|l|1: for a warning message (logging level CRITICAL, displayed by default)
    - error|e|exception|raise|r|2: for a raised exception

Example:
    export GIT_PYTHON_REFRESH=quiet
[2024-05-02T20:25:39.394+0000] {logging_and_warnings.py:72} WARNING - /home/***/.local/lib/python3.7/site-packages/sklearn/linear_model/_logistic.py:818: ConvergenceWarning: lbfgs failed to converge (status=1):
STOP: TOTAL NO. of ITERATIONS REACHED LIMIT.

Increase the number of iterations (max_iter) or scale the data as shown in:
    https://scikit-learn.org/stable/modules/preprocessing.html
Please also refer to the documentation for alternative solver options:
    https://scikit-learn.org/stable/modules/linear_model.html#logistic-regression
  extra_warning_msg=_LOGISTIC_SOLVER_CONVERGENCE_MSG,

[2024-05-02T20:25:39.789+0000] {logging_mixin.py:149} WARNING - 2024/05/02 20:25:39 WARNING mlflow.sklearn.utils: Failed to import matplotlib (error: ModuleNotFoundError("No module named 'matplotlib'")). Skipping artifact logging.
[2024-05-02T20:25:39.866+0000] {logging_mixin.py:149} WARNING - 2024/05/02 20:25:39 WARNING mlflow.utils.autologging_utils: Encountered unexpected error during sklearn autologging: [Errno 13] Permission denied: '/mlflow'
[2024-05-02T20:25:45.439+0000] {warnings.py:110} WARNING - /home/***/.local/lib/python3.7/site-packages/_distutils_hack/__init__.py:33: UserWarning: Setuptools is replacing distutils.
  warnings.warn("Setuptools is replacing distutils.")

[2024-05-02T20:25:45.456+0000] {taskinstance.py:1847} ERROR - Task failed with exception
Traceback (most recent call last):
  File "/home/airflow/.local/lib/python3.7/site-packages/airflow/operators/python.py", line 181, in execute
    return_value = self.execute_callable()
  File "/home/airflow/.local/lib/python3.7/site-packages/airflow/operators/python.py", line 198, in execute_callable
    return self.python_callable(*self.op_args, **self.op_kwargs)
  File "/opt/airflow/dags/dag1.py", line 57, in train_model
    mlflow.sklearn.log_model(logistic_classifier, "model")
  File "/home/airflow/.local/lib/python3.7/site-packages/mlflow/sklearn/__init__.py", line 420, in log_model
    pyfunc_predict_fn=pyfunc_predict_fn,
  File "/home/airflow/.local/lib/python3.7/site-packages/mlflow/models/model.py", line 374, in log
    mlflow.tracking.fluent.log_artifacts(local_path, mlflow_model.artifact_path)
  File "/home/airflow/.local/lib/python3.7/site-packages/mlflow/tracking/fluent.py", line 813, in log_artifacts
    MlflowClient().log_artifacts(run_id, local_dir, artifact_path)
  File "/home/airflow/.local/lib/python3.7/site-packages/mlflow/tracking/client.py", line 1182, in log_artifacts
    self._tracking_client.log_artifacts(run_id, local_dir, artifact_path)
  File "/home/airflow/.local/lib/python3.7/site-packages/mlflow/tracking/_tracking_service/client.py", line 469, in log_artifacts
    self._get_artifact_repo(run_id).log_artifacts(local_dir, artifact_path)
  File "/home/airflow/.local/lib/python3.7/site-packages/mlflow/store/artifact/local_artifact_repo.py", line 57, in log_artifacts
    mkdir(artifact_dir)
  File "/home/airflow/.local/lib/python3.7/site-packages/mlflow/utils/file_utils.py", line 121, in mkdir
    raise e
  File "/home/airflow/.local/lib/python3.7/site-packages/mlflow/utils/file_utils.py", line 118, in mkdir
    os.makedirs(target)
  File "/usr/local/lib/python3.7/os.py", line 213, in makedirs
    makedirs(head, exist_ok=exist_ok)
  File "/usr/local/lib/python3.7/os.py", line 213, in makedirs
    makedirs(head, exist_ok=exist_ok)
  File "/usr/local/lib/python3.7/os.py", line 213, in makedirs
    makedirs(head, exist_ok=exist_ok)
  [Previous line repeated 2 more times]
  File "/usr/local/lib/python3.7/os.py", line 223, in makedirs
    mkdir(name, mode)
PermissionError: [Errno 13] Permission denied: '/mlflow'
[2024-05-02T20:25:45.483+0000] {taskinstance.py:1373} INFO - Marking task as UP_FOR_RETRY. dag_id=diabetes_prediction, task_id=train_model, execution_date=20240502T202504, start_date=20240502T202528, end_date=20240502T202545
[2024-05-02T20:25:45.508+0000] {standard_task_runner.py:109} ERROR - Failed to execute job 145 for task train_model ([Errno 13] Permission denied: '/mlflow'; 144)
[2024-05-02T20:25:45.555+0000] {local_task_job_runner.py:232} INFO - Task exited with return code 1
[2024-05-02T20:25:45.605+0000] {taskinstance.py:2674} INFO - 0 downstream tasks scheduled from follow-on schedule check
